<?xml version="1.0" ?>
<robot name="niryo_one">
  <!-- Properties -->
  <!-- Links -->
  <link name="world"/>
  <link name="base_link">
	</link>
  <link name="shoulder_link">
	</link>
  <link name="arm_link">
	</link>
  <link name="elbow_link">
	</link>
  <link name="forearm_link">
	</link>
  <link name="wrist_link">
	</link>
  <link name="hand_link">
	</link>
  <link name="tool_link">
	</link>
  <!--Joints -->
  <joint name="joint_world" type="fixed">
    <parent link="world"/>
    <child link="base_link"/>
    <origin rpy="0 0 0" xyz="0 0 0"/>
  </joint>
  <joint name="joint_1" type="revolute">
    <parent link="base_link"/>
    <child link="shoulder_link"/>
    <origin rpy="0 0 0" xyz="0 0 0.103"/>
    <axis xyz="0 0 1"/>
    <limit effort="1" lower="-3.05433" upper="3.05433" velocity="1.0"/>
  </joint>
  <joint name="joint_2" type="revolute">
    <parent link="shoulder_link"/>
    <child link="arm_link"/>
    <origin rpy="1.570796326795 -1.570796326795 0" xyz="0 0 0.08"/>
    <limit effort="1" lower="-1.570796326795" upper="0.628319" velocity="1.0"/>
    <axis xyz="0 0 1"/>
  </joint>
  <joint name="joint_3" type="revolute">
    <parent link="arm_link"/>
    <child link="elbow_link"/>
    <origin rpy="0 0 -1.570796326795" xyz="0.21004 0.0 0"/>
    <limit effort="1" lower="-1.401" upper="0.994838" velocity="1.0"/>
    <axis xyz="0 0 1"/>
  </joint>
  <joint name="joint_4" type="revolute">
    <parent link="elbow_link"/>
    <child link="forearm_link"/>
    <origin rpy="0 1.570796326795 0" xyz="0.037 0.032 0"/>
    <limit effort="1" lower="-2.61799" upper="2.61799" velocity="1.0"/>
    <axis xyz="0 0 1"/>
  </joint>
  <joint name="joint_5" type="revolute">
    <parent link="forearm_link"/>
    <child link="wrist_link"/>
    <origin rpy="0 -1.570796326795 0" xyz="0 0 0.18"/>
    <limit effort="1" lower="-2.26893" upper="2.26893" velocity="1.0"/>
    <axis xyz="0 0 1"/>
  </joint>
  <joint name="joint_6" type="revolute">
    <parent link="wrist_link"/>
    <child link="hand_link"/>
    <origin rpy="0 1.570796326795 0" xyz="0.018 0 0"/>
    <limit effort="1" lower="-2.57" upper="2.57" velocity="1.0"/>
    <axis xyz="0 0 1"/>
  </joint>
  <joint name="hand_tool_joint" type="fixed">
    <parent link="hand_link"/>
    <child link="tool_link"/>
    <origin rpy="-1.570796326795 -1.570796326795 0" xyz="0 0 0.0"/>
  </joint>
</robot>
